I tensorflow/stream_executor/dso_loader.cc:108] successfully opened CUDA library libcublas.so.7.5 locally
I tensorflow/stream_executor/dso_loader.cc:108] successfully opened CUDA library libcudnn.so.5 locally
I tensorflow/stream_executor/dso_loader.cc:108] successfully opened CUDA library libcufft.so.7.5 locally
I tensorflow/stream_executor/dso_loader.cc:108] successfully opened CUDA library libcuda.so.1 locally
I tensorflow/stream_executor/dso_loader.cc:108] successfully opened CUDA library libcurand.so.7.5 locally
I tensorflow/core/common_runtime/gpu/gpu_init.cc:102] Found device 0 with properties: 
name: Tesla K40m
major: 3 minor: 5 memoryClockRate (GHz) 0.745
pciBusID 0000:02:00.0
Total memory: 11.17GiB
Free memory: 11.10GiB
W tensorflow/stream_executor/cuda/cuda_driver.cc:572] creating context when one is currently active; existing: 0x43ea8e0
I tensorflow/core/common_runtime/gpu/gpu_init.cc:102] Found device 1 with properties: 
name: Tesla K40m
major: 3 minor: 5 memoryClockRate (GHz) 0.745
pciBusID 0000:82:00.0
Total memory: 11.17GiB
Free memory: 11.10GiB
I tensorflow/core/common_runtime/gpu/gpu_init.cc:59] cannot enable peer access from device ordinal 0 to device ordinal 1
I tensorflow/core/common_runtime/gpu/gpu_init.cc:59] cannot enable peer access from device ordinal 1 to device ordinal 0
I tensorflow/core/common_runtime/gpu/gpu_init.cc:126] DMA: 0 1 
I tensorflow/core/common_runtime/gpu/gpu_init.cc:136] 0:   Y N 
I tensorflow/core/common_runtime/gpu/gpu_init.cc:136] 1:   N Y 
I tensorflow/core/common_runtime/gpu/gpu_device.cc:838] Creating TensorFlow device (/gpu:0) -> (device: 0, name: Tesla K40m, pci bus id: 0000:02:00.0)
I tensorflow/core/common_runtime/gpu/gpu_device.cc:838] Creating TensorFlow device (/gpu:1) -> (device: 1, name: Tesla K40m, pci bus id: 0000:82:00.0)
iteration : 0, validation loss : 2.30258, validation_accuracy0.16
Traceback (most recent call last):
  File "train_model.py", line 438, in <module>
    tf.app.run()
  File "/hpc/sw/python-2.7.11/lib/python2.7/site-packages/tensorflow/python/platform/app.py", line 30, in run
    sys.exit(main(sys.argv))
  File "train_model.py", line 400, in main
    train()
  File "train_model.py", line 161, in train
    np.save(FLAGS.checkpoint_dir +"/ConvNet/flatten", flatsave)
  File "/hpc/sw/python-2.7.11/lib/python2.7/site-packages/numpy/lib/npyio.py", line 477, in save
    fid = open(file, "wb")
IOError: [Errno 2] No such file or directory: './checkpoints/ConvNet/flatten.npy'
